"POST /user/ HTTP/1.1" 201 92
C:\Users\samba\ARMS\api_arms\api_arms\settings.py changed, reloading.
Watching for file changes with StatReloader
Watching for file changes with StatReloader
"POST /user/ HTTP/1.1" 201 92
Watching for file changes with StatReloader
"GET /person HTTP/1.1" 301 0
Internal Server Error: /person/
Traceback (most recent call last):
  File "C:\Users\Lenovo\anaconda3\Lib\site-packages\django\core\handlers\exception.py", line 55, in inner
    response = get_response(request)
               ^^^^^^^^^^^^^^^^^^^^^
  File "C:\Users\Lenovo\anaconda3\Lib\site-packages\django\core\handlers\base.py", line 197, in _get_response
    response = wrapped_callback(request, *callback_args, **callback_kwargs)
               ^^^^^^^^^^^^^^^^^^^^^^^^^^^^^^^^^^^^^^^^^^^^^^^^^^^^^^^^^^^^
  File "C:\Users\Lenovo\anaconda3\Lib\site-packages\django\views\decorators\csrf.py", line 56, in wrapper_view
    return view_func(*args, **kwargs)
           ^^^^^^^^^^^^^^^^^^^^^^^^^^
  File "C:\Users\Lenovo\anaconda3\Lib\site-packages\django\views\generic\base.py", line 104, in view
    return self.dispatch(request, *args, **kwargs)
           ^^^^^^^^^^^^^^^^^^^^^^^^^^^^^^^^^^^^^^^
  File "C:\Users\Lenovo\anaconda3\Lib\site-packages\rest_framework\views.py", line 509, in dispatch
    response = self.handle_exception(exc)
               ^^^^^^^^^^^^^^^^^^^^^^^^^^
  File "C:\Users\Lenovo\anaconda3\Lib\site-packages\rest_framework\views.py", line 469, in handle_exception
    self.raise_uncaught_exception(exc)
  File "C:\Users\Lenovo\anaconda3\Lib\site-packages\rest_framework\views.py", line 480, in raise_uncaught_exception
    raise exc
  File "C:\Users\Lenovo\anaconda3\Lib\site-packages\rest_framework\views.py", line 497, in dispatch
    self.initial(request, *args, **kwargs)
  File "C:\Users\Lenovo\anaconda3\Lib\site-packages\rest_framework\views.py", line 415, in initial
    self.check_permissions(request)
  File "C:\Users\Lenovo\anaconda3\Lib\site-packages\rest_framework\views.py", line 332, in check_permissions
    if not permission.has_permission(request, self):
           ^^^^^^^^^^^^^^^^^^^^^^^^^^^^^^^^^^^^^^^^
  File "C:\Samba sessions\DockerTests\ARMS\api_arms\base\authentication.py", line 35, in has_permission
    role_inst = request.user.role
                ^^^^^^^^^^^^^^^^^
AttributeError: 'AnonymousUser' object has no attribute 'role'
"GET /person/ HTTP/1.1" 500 145
Not Found: /favicon.ico
"GET /favicon.ico HTTP/1.1" 404 179
Internal Server Error: /person/
Traceback (most recent call last):
  File "C:\Users\Lenovo\anaconda3\Lib\site-packages\django\core\handlers\exception.py", line 55, in inner
    response = get_response(request)
               ^^^^^^^^^^^^^^^^^^^^^
  File "C:\Users\Lenovo\anaconda3\Lib\site-packages\django\core\handlers\base.py", line 197, in _get_response
    response = wrapped_callback(request, *callback_args, **callback_kwargs)
               ^^^^^^^^^^^^^^^^^^^^^^^^^^^^^^^^^^^^^^^^^^^^^^^^^^^^^^^^^^^^
  File "C:\Users\Lenovo\anaconda3\Lib\site-packages\django\views\decorators\csrf.py", line 56, in wrapper_view
    return view_func(*args, **kwargs)
           ^^^^^^^^^^^^^^^^^^^^^^^^^^
  File "C:\Users\Lenovo\anaconda3\Lib\site-packages\django\views\generic\base.py", line 104, in view
    return self.dispatch(request, *args, **kwargs)
           ^^^^^^^^^^^^^^^^^^^^^^^^^^^^^^^^^^^^^^^
  File "C:\Users\Lenovo\anaconda3\Lib\site-packages\rest_framework\views.py", line 509, in dispatch
    response = self.handle_exception(exc)
               ^^^^^^^^^^^^^^^^^^^^^^^^^^
  File "C:\Users\Lenovo\anaconda3\Lib\site-packages\rest_framework\views.py", line 469, in handle_exception
    self.raise_uncaught_exception(exc)
  File "C:\Users\Lenovo\anaconda3\Lib\site-packages\rest_framework\views.py", line 480, in raise_uncaught_exception
    raise exc
  File "C:\Users\Lenovo\anaconda3\Lib\site-packages\rest_framework\views.py", line 497, in dispatch
    self.initial(request, *args, **kwargs)
  File "C:\Users\Lenovo\anaconda3\Lib\site-packages\rest_framework\views.py", line 415, in initial
    self.check_permissions(request)
  File "C:\Users\Lenovo\anaconda3\Lib\site-packages\rest_framework\views.py", line 332, in check_permissions
    if not permission.has_permission(request, self):
           ^^^^^^^^^^^^^^^^^^^^^^^^^^^^^^^^^^^^^^^^
  File "C:\Samba sessions\DockerTests\ARMS\api_arms\base\authentication.py", line 35, in has_permission
    role_inst = request.user.role
                ^^^^^^^^^^^^^^^^^
AttributeError: 'AnonymousUser' object has no attribute 'role'
"GET /person/ HTTP/1.1" 500 145
C:\Samba sessions\DockerTests\ARMS\api_arms\app1\urls.py changed, reloading.
Watching for file changes with StatReloader
Internal Server Error: /person1/
Traceback (most recent call last):
  File "C:\Users\Lenovo\anaconda3\Lib\site-packages\django\core\handlers\exception.py", line 55, in inner
    response = get_response(request)
               ^^^^^^^^^^^^^^^^^^^^^
  File "C:\Users\Lenovo\anaconda3\Lib\site-packages\django\core\handlers\base.py", line 197, in _get_response
    response = wrapped_callback(request, *callback_args, **callback_kwargs)
               ^^^^^^^^^^^^^^^^^^^^^^^^^^^^^^^^^^^^^^^^^^^^^^^^^^^^^^^^^^^^
  File "C:\Users\Lenovo\anaconda3\Lib\site-packages\django\views\decorators\csrf.py", line 56, in wrapper_view
    return view_func(*args, **kwargs)
           ^^^^^^^^^^^^^^^^^^^^^^^^^^
  File "C:\Users\Lenovo\anaconda3\Lib\site-packages\django\views\generic\base.py", line 104, in view
    return self.dispatch(request, *args, **kwargs)
           ^^^^^^^^^^^^^^^^^^^^^^^^^^^^^^^^^^^^^^^
  File "C:\Users\Lenovo\anaconda3\Lib\site-packages\rest_framework\views.py", line 509, in dispatch
    response = self.handle_exception(exc)
               ^^^^^^^^^^^^^^^^^^^^^^^^^^
  File "C:\Users\Lenovo\anaconda3\Lib\site-packages\rest_framework\views.py", line 469, in handle_exception
    self.raise_uncaught_exception(exc)
  File "C:\Users\Lenovo\anaconda3\Lib\site-packages\rest_framework\views.py", line 480, in raise_uncaught_exception
    raise exc
  File "C:\Users\Lenovo\anaconda3\Lib\site-packages\rest_framework\views.py", line 497, in dispatch
    self.initial(request, *args, **kwargs)
  File "C:\Users\Lenovo\anaconda3\Lib\site-packages\rest_framework\views.py", line 415, in initial
    self.check_permissions(request)
  File "C:\Users\Lenovo\anaconda3\Lib\site-packages\rest_framework\views.py", line 332, in check_permissions
    if not permission.has_permission(request, self):
           ^^^^^^^^^^^^^^^^^^^^^^^^^^^^^^^^^^^^^^^^
  File "C:\Samba sessions\DockerTests\ARMS\api_arms\base\authentication.py", line 35, in has_permission
    role_inst = request.user.role
                ^^^^^^^^^^^^^^^^^
AttributeError: 'AnonymousUser' object has no attribute 'role'
"GET /person1/ HTTP/1.1" 500 145
Not Found: /person1/sdfhfdlfd/
"GET /person1/sdfhfdlfd/ HTTP/1.1" 404 179
Not Found: /person1/sdfhfdlfd/ree/
Not Found: /person/ef/gre/fe/
"GET /person1/sdfhfdlfd/ree/ HTTP/1.1" 404 179
- Broken pipe from ('127.0.0.1', 52803)
Watching for file changes with StatReloader
Not Found: /person1/sdfhfdlfd/ree/
"GET /person1/sdfhfdlfd/ree/ HTTP/1.1" 404 179
Not Found: /person1/sdfhfdlfd/ree/
"GET /person1/sdfhfdlfd/ree/? HTTP/1.1" 404 179
Not Found: /person1/sdfhfdlfd/ree/
"GET /person1/sdfhfdlfd/ree/?name= HTTP/1.1" 404 179
Not Found: /person1/sdfhfdlfd/ree/
"GET /person1/sdfhfdlfd/ree/?name=%27sd%27 HTTP/1.1" 404 179
Internal Server Error: /person1/
Traceback (most recent call last):
  File "C:\Users\Lenovo\anaconda3\Lib\site-packages\django\core\handlers\exception.py", line 55, in inner
    response = get_response(request)
               ^^^^^^^^^^^^^^^^^^^^^
  File "C:\Users\Lenovo\anaconda3\Lib\site-packages\django\core\handlers\base.py", line 197, in _get_response
    response = wrapped_callback(request, *callback_args, **callback_kwargs)
               ^^^^^^^^^^^^^^^^^^^^^^^^^^^^^^^^^^^^^^^^^^^^^^^^^^^^^^^^^^^^
  File "C:\Users\Lenovo\anaconda3\Lib\site-packages\django\views\decorators\csrf.py", line 56, in wrapper_view
    return view_func(*args, **kwargs)
           ^^^^^^^^^^^^^^^^^^^^^^^^^^
  File "C:\Users\Lenovo\anaconda3\Lib\site-packages\django\views\generic\base.py", line 104, in view
    return self.dispatch(request, *args, **kwargs)
           ^^^^^^^^^^^^^^^^^^^^^^^^^^^^^^^^^^^^^^^
  File "C:\Users\Lenovo\anaconda3\Lib\site-packages\rest_framework\views.py", line 509, in dispatch
    response = self.handle_exception(exc)
               ^^^^^^^^^^^^^^^^^^^^^^^^^^
  File "C:\Users\Lenovo\anaconda3\Lib\site-packages\rest_framework\views.py", line 469, in handle_exception
    self.raise_uncaught_exception(exc)
  File "C:\Users\Lenovo\anaconda3\Lib\site-packages\rest_framework\views.py", line 480, in raise_uncaught_exception
    raise exc
  File "C:\Users\Lenovo\anaconda3\Lib\site-packages\rest_framework\views.py", line 497, in dispatch
    self.initial(request, *args, **kwargs)
  File "C:\Users\Lenovo\anaconda3\Lib\site-packages\rest_framework\views.py", line 415, in initial
    self.check_permissions(request)
  File "C:\Users\Lenovo\anaconda3\Lib\site-packages\rest_framework\views.py", line 332, in check_permissions
    if not permission.has_permission(request, self):
           ^^^^^^^^^^^^^^^^^^^^^^^^^^^^^^^^^^^^^^^^
  File "C:\Samba sessions\DockerTests\ARMS\api_arms\base\authentication.py", line 35, in has_permission
    role_inst = request.user.role
                ^^^^^^^^^^^^^^^^^
AttributeError: 'AnonymousUser' object has no attribute 'role'
"GET /person1/?name=%27sd%27 HTTP/1.1" 500 145
"GET /person1?name=%27sd%27&age=12 HTTP/1.1" 301 0
Internal Server Error: /person1/
Traceback (most recent call last):
  File "C:\Users\Lenovo\anaconda3\Lib\site-packages\django\core\handlers\exception.py", line 55, in inner
    response = get_response(request)
               ^^^^^^^^^^^^^^^^^^^^^
  File "C:\Users\Lenovo\anaconda3\Lib\site-packages\django\core\handlers\base.py", line 197, in _get_response
    response = wrapped_callback(request, *callback_args, **callback_kwargs)
               ^^^^^^^^^^^^^^^^^^^^^^^^^^^^^^^^^^^^^^^^^^^^^^^^^^^^^^^^^^^^
  File "C:\Users\Lenovo\anaconda3\Lib\site-packages\django\views\decorators\csrf.py", line 56, in wrapper_view
    return view_func(*args, **kwargs)
           ^^^^^^^^^^^^^^^^^^^^^^^^^^
  File "C:\Users\Lenovo\anaconda3\Lib\site-packages\django\views\generic\base.py", line 104, in view
    return self.dispatch(request, *args, **kwargs)
           ^^^^^^^^^^^^^^^^^^^^^^^^^^^^^^^^^^^^^^^
  File "C:\Users\Lenovo\anaconda3\Lib\site-packages\rest_framework\views.py", line 509, in dispatch
    response = self.handle_exception(exc)
               ^^^^^^^^^^^^^^^^^^^^^^^^^^
  File "C:\Users\Lenovo\anaconda3\Lib\site-packages\rest_framework\views.py", line 469, in handle_exception
    self.raise_uncaught_exception(exc)
  File "C:\Users\Lenovo\anaconda3\Lib\site-packages\rest_framework\views.py", line 480, in raise_uncaught_exception
    raise exc
  File "C:\Users\Lenovo\anaconda3\Lib\site-packages\rest_framework\views.py", line 497, in dispatch
    self.initial(request, *args, **kwargs)
  File "C:\Users\Lenovo\anaconda3\Lib\site-packages\rest_framework\views.py", line 415, in initial
    self.check_permissions(request)
  File "C:\Users\Lenovo\anaconda3\Lib\site-packages\rest_framework\views.py", line 332, in check_permissions
    if not permission.has_permission(request, self):
           ^^^^^^^^^^^^^^^^^^^^^^^^^^^^^^^^^^^^^^^^
  File "C:\Samba sessions\DockerTests\ARMS\api_arms\base\authentication.py", line 35, in has_permission
    role_inst = request.user.role
                ^^^^^^^^^^^^^^^^^
AttributeError: 'AnonymousUser' object has no attribute 'role'
"GET /person1/?name=%27sd%27&age=12 HTTP/1.1" 500 145
Internal Server Error: /person1/
Traceback (most recent call last):
  File "C:\Users\Lenovo\anaconda3\Lib\site-packages\django\core\handlers\exception.py", line 55, in inner
    response = get_response(request)
               ^^^^^^^^^^^^^^^^^^^^^
  File "C:\Users\Lenovo\anaconda3\Lib\site-packages\django\core\handlers\base.py", line 197, in _get_response
    response = wrapped_callback(request, *callback_args, **callback_kwargs)
               ^^^^^^^^^^^^^^^^^^^^^^^^^^^^^^^^^^^^^^^^^^^^^^^^^^^^^^^^^^^^
  File "C:\Users\Lenovo\anaconda3\Lib\site-packages\django\views\decorators\csrf.py", line 56, in wrapper_view
    return view_func(*args, **kwargs)
           ^^^^^^^^^^^^^^^^^^^^^^^^^^
  File "C:\Users\Lenovo\anaconda3\Lib\site-packages\django\views\generic\base.py", line 104, in view
    return self.dispatch(request, *args, **kwargs)
           ^^^^^^^^^^^^^^^^^^^^^^^^^^^^^^^^^^^^^^^
  File "C:\Users\Lenovo\anaconda3\Lib\site-packages\rest_framework\views.py", line 509, in dispatch
    response = self.handle_exception(exc)
               ^^^^^^^^^^^^^^^^^^^^^^^^^^
  File "C:\Users\Lenovo\anaconda3\Lib\site-packages\rest_framework\views.py", line 469, in handle_exception
    self.raise_uncaught_exception(exc)
  File "C:\Users\Lenovo\anaconda3\Lib\site-packages\rest_framework\views.py", line 480, in raise_uncaught_exception
    raise exc
  File "C:\Users\Lenovo\anaconda3\Lib\site-packages\rest_framework\views.py", line 497, in dispatch
    self.initial(request, *args, **kwargs)
  File "C:\Users\Lenovo\anaconda3\Lib\site-packages\rest_framework\views.py", line 415, in initial
    self.check_permissions(request)
  File "C:\Users\Lenovo\anaconda3\Lib\site-packages\rest_framework\views.py", line 332, in check_permissions
    if not permission.has_permission(request, self):
           ^^^^^^^^^^^^^^^^^^^^^^^^^^^^^^^^^^^^^^^^
  File "C:\Samba sessions\DockerTests\ARMS\api_arms\base\authentication.py", line 35, in has_permission
    role_inst = request.user.role
                ^^^^^^^^^^^^^^^^^
AttributeError: 'AnonymousUser' object has no attribute 'role'
"GET /person1/?name=%27sd%27&age=12 HTTP/1.1" 500 145
Internal Server Error: /person1/
Traceback (most recent call last):
  File "C:\Users\Lenovo\anaconda3\Lib\site-packages\django\core\handlers\exception.py", line 55, in inner
    response = get_response(request)
               ^^^^^^^^^^^^^^^^^^^^^
  File "C:\Users\Lenovo\anaconda3\Lib\site-packages\django\core\handlers\base.py", line 197, in _get_response
    response = wrapped_callback(request, *callback_args, **callback_kwargs)
               ^^^^^^^^^^^^^^^^^^^^^^^^^^^^^^^^^^^^^^^^^^^^^^^^^^^^^^^^^^^^
  File "C:\Users\Lenovo\anaconda3\Lib\site-packages\django\views\decorators\csrf.py", line 56, in wrapper_view
    return view_func(*args, **kwargs)
           ^^^^^^^^^^^^^^^^^^^^^^^^^^
  File "C:\Users\Lenovo\anaconda3\Lib\site-packages\django\views\generic\base.py", line 104, in view
    return self.dispatch(request, *args, **kwargs)
           ^^^^^^^^^^^^^^^^^^^^^^^^^^^^^^^^^^^^^^^
  File "C:\Users\Lenovo\anaconda3\Lib\site-packages\rest_framework\views.py", line 509, in dispatch
    response = self.handle_exception(exc)
               ^^^^^^^^^^^^^^^^^^^^^^^^^^
  File "C:\Users\Lenovo\anaconda3\Lib\site-packages\rest_framework\views.py", line 469, in handle_exception
    self.raise_uncaught_exception(exc)
  File "C:\Users\Lenovo\anaconda3\Lib\site-packages\rest_framework\views.py", line 480, in raise_uncaught_exception
    raise exc
  File "C:\Users\Lenovo\anaconda3\Lib\site-packages\rest_framework\views.py", line 497, in dispatch
    self.initial(request, *args, **kwargs)
  File "C:\Users\Lenovo\anaconda3\Lib\site-packages\rest_framework\views.py", line 415, in initial
    self.check_permissions(request)
  File "C:\Users\Lenovo\anaconda3\Lib\site-packages\rest_framework\views.py", line 332, in check_permissions
    if not permission.has_permission(request, self):
           ^^^^^^^^^^^^^^^^^^^^^^^^^^^^^^^^^^^^^^^^
  File "C:\Samba sessions\DockerTests\ARMS\api_arms\base\authentication.py", line 35, in has_permission
    role_inst = request.user.role
                ^^^^^^^^^^^^^^^^^
AttributeError: 'AnonymousUser' object has no attribute 'role'
"GET /person1/?name=%27sd%27&age=12 HTTP/1.1" 500 145
C:\Samba sessions\DockerTests\ARMS\api_arms\api_arms\settings.py changed, reloading.
Watching for file changes with StatReloader
Internal Server Error: /person1/
Traceback (most recent call last):
  File "C:\Users\Lenovo\anaconda3\Lib\site-packages\django\core\handlers\exception.py", line 55, in inner
    response = get_response(request)
               ^^^^^^^^^^^^^^^^^^^^^
  File "C:\Users\Lenovo\anaconda3\Lib\site-packages\django\core\handlers\base.py", line 197, in _get_response
    response = wrapped_callback(request, *callback_args, **callback_kwargs)
               ^^^^^^^^^^^^^^^^^^^^^^^^^^^^^^^^^^^^^^^^^^^^^^^^^^^^^^^^^^^^
  File "C:\Users\Lenovo\anaconda3\Lib\site-packages\django\views\decorators\csrf.py", line 56, in wrapper_view
    return view_func(*args, **kwargs)
           ^^^^^^^^^^^^^^^^^^^^^^^^^^
  File "C:\Users\Lenovo\anaconda3\Lib\site-packages\django\views\generic\base.py", line 104, in view
    return self.dispatch(request, *args, **kwargs)
           ^^^^^^^^^^^^^^^^^^^^^^^^^^^^^^^^^^^^^^^
  File "C:\Users\Lenovo\anaconda3\Lib\site-packages\rest_framework\views.py", line 509, in dispatch
    response = self.handle_exception(exc)
               ^^^^^^^^^^^^^^^^^^^^^^^^^^
  File "C:\Users\Lenovo\anaconda3\Lib\site-packages\rest_framework\views.py", line 469, in handle_exception
    self.raise_uncaught_exception(exc)
  File "C:\Users\Lenovo\anaconda3\Lib\site-packages\rest_framework\views.py", line 480, in raise_uncaught_exception
    raise exc
  File "C:\Users\Lenovo\anaconda3\Lib\site-packages\rest_framework\views.py", line 497, in dispatch
    self.initial(request, *args, **kwargs)
  File "C:\Users\Lenovo\anaconda3\Lib\site-packages\rest_framework\views.py", line 415, in initial
    self.check_permissions(request)
  File "C:\Users\Lenovo\anaconda3\Lib\site-packages\rest_framework\views.py", line 332, in check_permissions
    if not permission.has_permission(request, self):
           ^^^^^^^^^^^^^^^^^^^^^^^^^^^^^^^^^^^^^^^^
  File "C:\Samba sessions\DockerTests\ARMS\api_arms\base\authentication.py", line 35, in has_permission
    role_inst = request.user.role
                ^^^^^^^^^^^^^^^^^
AttributeError: 'AnonymousUser' object has no attribute 'role'
"GET /person1/?name=%27sd%27&age=12 HTTP/1.1" 500 98631
C:\Samba sessions\DockerTests\ARMS\api_arms\api_arms\settings.py changed, reloading.
Watching for file changes with StatReloader
"GET /person1/?name=%27sd%27&age=12 HTTP/1.1" 200 2
"GET /person1/?name=sd&age=12 HTTP/1.1" 200 2
"GET /person1/?name=sd,ghjjjfj&age=12 HTTP/1.1" 200 2
Not Found: /person1/name=sd,ghjjjfj&age=12
"GET /person1/name=sd,ghjjjfj&age=12 HTTP/1.1" 404 8051
Watching for file changes with StatReloader
Not Found: /person1/name=sd,ghjjjfj&age=12
"GET /person1/name=sd,ghjjjfj&age=12 HTTP/1.1" 404 8051
"GET /person1/?name=sd,ghjjjfj&age=12 HTTP/1.1" 200 2
C:\Samba sessions\DockerTests\ARMS\api_arms\api_arms\settings.py changed, reloading.
Watching for file changes with StatReloader
Watching for file changes with StatReloader
